Workbook
Name A_SETT: Assenze!$A$5:$A$204
Name A_PERS: Assenze!$C$5:$C$204
Name A_TIPO: Assenze!$D$5:$D$204
Name A_DATA: Assenze!$E$5:$E$204
Name PARTECIPANTI: Partecipanti!$B$5:$B$9

Sheet Regole
A1: SERVIZIO DI TURNAZIONE AUTO
A2: Trinitapoli → Foggia → Trinitapoli · Regolamento e istruzioni d'uso
A5: 1. DATI DEL SERVIZIO
B6: Tratta | C6: Trinitapoli → Foggia → Trinitapoli
B7: Frequenza | C7: 5 giorni a settimana, dal lunedì al venerdì
B8: Partecipanti | C8: Nicola, Stefano, Rocco, Giuseppe, Savino
B9: Periodo coperto | C9: 28/09/2026 – 25/12/2026 (13 settimane)
B10: Ordine base di turnazione | C10: Lunedì: Nicola · Martedì: Stefano · Mercoledì: Rocco · Giovedì: Giuseppe · Venerdì: Savino
A12: 2. REGOLE DI GESTIONE DEI TURNI
B13: R1 – Licenza settimana intera | C13: Chi è in licenza per l'intera settimana NON deve recuperare il turno perso. Il turno viene coperto da un sostituto e si considera chiuso.
B14: R2 – Attività esterna settimana intera | C14: Chi è in attività esterna per l'intera settimana NON deve recuperare il turno perso. Vale la stessa regola della licenza.
B15: R3 – Assenza per altro motivo | C15: Qualunque mancata presa della macchina per motivi diversi da R1 e R2 genera un turno da recuperare nella settimana successiva.
B16: R4 – Scelta del sostituto | C16: Il giorno scoperto viene assegnato a chi ha accumulato finora il minor numero di doppi turni. A parità, si scorre l'ordine base a partire dal collega successivo all'assente. Così il doppio turno cade sempre su una turnazione diversa dalla prima e non ricade mai due volte di seguito sulla stessa persona.
B17: R5 – Modalità del recupero (solo R3) | C17: Nella settimana successiva chi ha saltato il turno guida due volte: il proprio giorno più il giorno di chi lo aveva sostituito. Il sostituto, quella settimana, è a riposo compensativo. Il bilancio dei turni torna in pari.
B18: R6 – Comunicazione del giovedì | C18: Entro il giovedì di ogni settimana vanno comunicate a tutti le posizioni della settimana successiva. Usare il foglio «Comunicazione Giovedì»: contiene il prospetto e il testo già pronto da inviare.
B19: R7 – Recupero non effettuabile | C19: Se chi deve recuperare è a sua volta assente nella settimana del recupero, il recupero non si perde: resta contabilizzato nel foglio «Riepilogo» alla voce «Recuperi da saldare».
A21: 3. COME SI USA IL FILE
B22: Foglio da compilare | C22: Solo «Assenze». Tutti gli altri fogli si aggiornano da soli.
B23: Come inserire un'assenza | C23: Una riga per ogni assenza: numero della settimana, nome, tipo di assenza dal menù a tendina e — solo per «Altro motivo» — la data del giorno saltato.
B24: Assenza di settimana intera | C24: Basta indicare settimana, nome e tipo: la data va lasciata vuota, la regola copre tutti e cinque i giorni.
B25: Dove si leggono i risultati | C25: «Turnazione» = calendario completo · «Comunicazione Giovedì» = prospetto da inviare · «Riepilogo» = conteggi e recuperi per persona.
B26: Colonne modificabili a mano | C26: Le celle su sfondo giallo. Tutte le altre contengono formule: non sovrascriverle.
A28: 4. LEGENDA DEI TIPI DI TURNO
B29: Ordinario | C29: Il turno si svolge secondo l'ordine base.
B30: Sostituzione (doppio turno) | C30: Il titolare è assente: guida un collega, che quella settimana prende la macchina due volte.
B31: Recupero | C31: Turno restituito da chi aveva saltato per motivo non giustificato; il collega che lo aveva sostituito è a riposo compensativo.
B32: DA ASSEGNARE | C32: Nessun sostituto disponibile in automatico (troppe assenze contemporanee): va deciso manualmente.

Sheet Partecipanti
A1: PARTECIPANTI E ORDINE BASE
A2: Trinitapoli → Foggia → Trinitapoli
A4: N. | B4: Nome | C4: Giorno base | D4: Tratta | E4: Note
A5: 1 | B5: Nicola | C5: Lunedì | D5: Trinitapoli → Foggia → Trinitapoli
A6: 2 | B6: Stefano | C6: Martedì | D6: Trinitapoli → Foggia → Trinitapoli
A7: 3 | B7: Rocco | C7: Mercoledì | D7: Trinitapoli → Foggia → Trinitapoli
A8: 4 | B8: Giuseppe | C8: Giovedì | D8: Trinitapoli → Foggia → Trinitapoli
A9: 5 | B9: Savino | C9: Venerdì | D9: Trinitapoli → Foggia → Trinitapoli
B11: Per cambiare un nominativo modificare la cella in colonna B: l'intero calendario si aggiorna automaticamente.

Sheet Assenze
A1: ASSENZE E IMPEDIMENTI
A2: Unico foglio da compilare a mano · le celle gialle sono editabili
A4: Settimana | B4: Periodo della settimana | C4: Persona | D4: Tipo di assenza | E4: Data (solo per «Altro motivo») | F4: Turno da recuperare? | G4: Note
B5: =IF($A5="","",TEXT(Calcoli!$AB$6+($A5-1)*7,"dd/mm/yyyy")&" - "&TEXT(Calcoli!$AB$6+($A5-1)*7+4,"dd/mm/yyyy")) | F5: =IF($D5="","",IF(OR($D5="Licenza - settimana intera",$D5="Attività esterna - settimana intera"),"NO - non recuperabile","SI - settimana successiva"))
B6: =IF($A6="","",TEXT(Calcoli!$AB$6+($A6-1)*7,"dd/mm/yyyy")&" - "&TEXT(Calcoli!$AB$6+($A6-1)*7+4,"dd/mm/yyyy")) | F6: =IF($D6="","",IF(OR($D6="Licenza - settimana intera",$D6="Attività esterna - settimana intera"),"NO - non recuperabile","SI - settimana successiva"))
B7: =IF($A7="","",TEXT(Calcoli!$AB$6+($A7-1)*7,"dd/mm/yyyy")&" - "&TEXT(Calcoli!$AB$6+($A7-1)*7+4,"dd/mm/yyyy")) | F7: =IF($D7="","",IF(OR($D7="Licenza - settimana intera",$D7="Attività esterna - settimana intera"),"NO - non recuperabile","SI - settimana successiva"))
B8: =IF($A8="","",TEXT(Calcoli!$AB$6+($A8-1)*7,"dd/mm/yyyy")&" - "&TEXT(Calcoli!$AB$6+($A8-1)*7+4,"dd/mm/yyyy")) | F8: =IF($D8="","",IF(OR($D8="Licenza - settimana intera",$D8="Attività esterna - settimana intera"),"NO - non recuperabile","SI - settimana successiva"))
B9: =IF($A9="","",TEXT(Calcoli!$AB$6+($A9-1)*7,"dd/mm/yyyy")&" - "&TEXT(Calcoli!$AB$6+($A9-1)*7+4,"dd/mm/yyyy")) | F9: =IF($D9="","",IF(OR($D9="Licenza - settimana intera",$D9="Attività esterna - settimana intera"),"NO - non recuperabile","SI - settimana successiva"))
B10: =IF($A10="","",TEXT(Calcoli!$AB$6+($A10-1)*7,"dd/mm/yyyy")&" - "&TEXT(Calcoli!$AB$6+($A10-1)*7+4,"dd/mm/yyyy")) | F10: =IF($D10="","",IF(OR($D10="Licenza - settimana intera",$D10="Attività esterna - settimana intera"),"NO - non recuperabile","SI - settimana successiva"))
B11: =IF($A11="","",TEXT(Calcoli!$AB$6+($A11-1)*7,"dd/mm/yyyy")&" - "&TEXT(Calcoli!$AB$6+($A11-1)*7+4,"dd/mm/yyyy")) | F11: =IF($D11="","",IF(OR($D11="Licenza - settimana intera",$D11="Attività esterna - settimana intera"),"NO - non recuperabile","SI - settimana successiva"))
B12: =IF($A12="","",TEXT(Calcoli!$AB$6+($A12-1)*7,"dd/mm/yyyy")&" - "&TEXT(Calcoli!$AB$6+($A12-1)*7+4,"dd/mm/yyyy")) | F12: =IF($D12="","",IF(OR($D12="Licenza - settimana intera",$D12="Attività esterna - settimana intera"),"NO - non recuperabile","SI - settimana successiva"))
B13: =IF($A13="","",TEXT(Calcoli!$AB$6+($A13-1)*7,"dd/mm/yyyy")&" - "&TEXT(Calcoli!$AB$6+($A13-1)*7+4,"dd/mm/yyyy")) | F13: =IF($D13="","",IF(OR($D13="Licenza - settimana intera",$D13="Attività esterna - settimana intera"),"NO - non recuperabile","SI - settimana successiva"))
B14: =IF($A14="","",TEXT(Calcoli!$AB$6+($A14-1)*7,"dd/mm/yyyy")&" - "&TEXT(Calcoli!$AB$6+($A14-1)*7+4,"dd/mm/yyyy")) | F14: =IF($D14="","",IF(OR($D14="Licenza - settimana intera",$D14="Attività esterna - settimana intera"),"NO - non recuperabile","SI - settimana successiva"))
B15: =IF($A15="","",TEXT(Calcoli!$AB$6+($A15-1)*7,"dd/mm/yyyy")&" - "&TEXT(Calcoli!$AB$6+($A15-1)*7+4,"dd/mm/yyyy")) | F15: =IF($D15="","",IF(OR($D15="Licenza - settimana intera",$D15="Attività esterna - settimana intera"),"NO - non recuperabile","SI - settimana successiva"))
B16: =IF($A16="","",TEXT(Calcoli!$AB$6+($A16-1)*7,"dd/mm/yyyy")&" - "&TEXT(Calcoli!$AB$6+($A16-1)*7+4,"dd/mm/yyyy")) | F16: =IF($D16="","",IF(OR($D16="Licenza - settimana intera",$D16="Attività esterna - settimana intera"),"NO - non recuperabile","SI - settimana successiva"))
... B204: =IF($A204="","",TEXT(Calcoli!$AB$6+($A204-1)*7,"dd/mm/yyyy")&" - "&TEXT(Calcoli!$AB$6+($A204-1)*7+4,"dd/mm/yyyy")) | F204: =IF($D204="","",IF(OR($D204="Licenza - settimana intera",$D204="Attività esterna - settimana intera"),"NO - non recuperabile","SI - settimana successiva"))

Sheet Turnazione
A1: CALENDARIO DELLA TURNAZIONE
A2: Trinitapoli → Foggia → Trinitapoli · 28/09/2026 – 25/12/2026 · calcolo automatico dal foglio «Assenze»
A3: Le colonne da D a I sono calcolate automaticamente. Compilare a mano solo la colonna «Note».
A5: Sett. | B5: Data | C5: Giorno | D5: Turno previsto | E5: Stato del titolare | F5: Conducente effettivo | G5: Tipo di turno | H5: Non guida (a riposo) | I5: Motivo della variazione | J5: Note
A6: 1 | B6: =Calcoli!$B6 | C6: Lunedì | D6: =Calcoli!$C6 | E6: =IF(Calcoli!$E6=0,"Presente",Calcoli!$D6) | F6: =Calcoli!$U6 | G6: =Calcoli!$V6 | H6: =Calcoli!$W6 | I6: =Calcoli!$X6
A7: 1 | B7: =Calcoli!$B7 | C7: Martedì | D7: =Calcoli!$C7 | E7: =IF(Calcoli!$E7=0,"Presente",Calcoli!$D7) | F7: =Calcoli!$U7 | G7: =Calcoli!$V7 | H7: =Calcoli!$W7 | I7: =Calcoli!$X7
A8: 1 | B8: =Calcoli!$B8 | C8: Mercoledì | D8: =Calcoli!$C8 | E8: =IF(Calcoli!$E8=0,"Presente",Calcoli!$D8) | F8: =Calcoli!$U8 | G8: =Calcoli!$V8 | H8: =Calcoli!$W8 | I8: =Calcoli!$X8
A9: 1 | B9: =Calcoli!$B9 | C9: Giovedì | D9: =Calcoli!$C9 | E9: =IF(Calcoli!$E9=0,"Presente",Calcoli!$D9) | F9: =Calcoli!$U9 | G9: =Calcoli!$V9 | H9: =Calcoli!$W9 | I9: =Calcoli!$X9
A10: 1 | B10: =Calcoli!$B10 | C10: Venerdì | D10: =Calcoli!$C10 | E10: =IF(Calcoli!$E10=0,"Presente",Calcoli!$D10) | F10: =Calcoli!$U10 | G10: =Calcoli!$V10 | H10: =Calcoli!$W10 | I10: =Calcoli!$X10
A11: 2 | B11: =Calcoli!$B11 | C11: Lunedì | D11: =Calcoli!$C11 | E11: =IF(Calcoli!$E11=0,"Presente",Calcoli!$D11) | F11: =Calcoli!$U11 | G11: =Calcoli!$V11 | H11: =Calcoli!$W11 | I11: =Calcoli!$X11
A12: 2 | B12: =Calcoli!$B12 | C12: Martedì | D12: =Calcoli!$C12 | E12: =IF(Calcoli!$E12=0,"Presente",Calcoli!$D12) | F12: =Calcoli!$U12 | G12: =Calcoli!$V12 | H12: =Calcoli!$W12 | I12: =Calcoli!$X12
A13: 2 | B13: =Calcoli!$B13 | C13: Mercoledì | D13: =Calcoli!$C13 | E13: =IF(Calcoli!$E13=0,"Presente",Calcoli!$D13) | F13: =Calcoli!$U13 | G13: =Calcoli!$V13 | H13: =Calcoli!$W13 | I13: =Calcoli!$X13
A14: 2 | B14: =Calcoli!$B14 | C14: Giovedì | D14: =Calcoli!$C14 | E14: =IF(Calcoli!$E14=0,"Presente",Calcoli!$D14) | F14: =Calcoli!$U14 | G14: =Calcoli!$V14 | H14: =Calcoli!$W14 | I14: =Calcoli!$X14
A15: 2 | B15: =Calcoli!$B15 | C15: Venerdì | D15: =Calcoli!$C15 | E15: =IF(Calcoli!$E15=0,"Presente",Calcoli!$D15) | F15: =Calcoli!$U15 | G15: =Calcoli!$V15 | H15: =Calcoli!$W15 | I15: =Calcoli!$X15
A16: 3 | B16: =Calcoli!$B16 | C16: Lunedì | D16: =Calcoli!$C16 | E16: =IF(Calcoli!$E16=0,"Presente",Calcoli!$D16) | F16: =Calcoli!$U16 | G16: =Calcoli!$V16 | H16: =Calcoli!$W16 | I16: =Calcoli!$X16
A17: 3 | B17: =Calcoli!$B17 | C17: Martedì | D17: =Calcoli!$C17 | E17: =IF(Calcoli!$E17=0,"Presente",Calcoli!$D17) | F17: =Calcoli!$U17 | G17: =Calcoli!$V17 | H17: =Calcoli!$W17 | I17: =Calcoli!$X17
... A70: 13 | B70: =Calcoli!$B70 | C70: Venerdì | D70: =Calcoli!$C70 | E70: =IF(Calcoli!$E70=0,"Presente",Calcoli!$D70) | F70: =Calcoli!$U70 | G70: =Calcoli!$V70 | H70: =Calcoli!$W70 | I70: =Calcoli!$X70

Sheet Comunicazione Giovedì
A1: COMUNICAZIONE DEL GIOVEDÌ
A2: Prospetto delle posizioni della settimana selezionata, da inviare ai partecipanti
B4: Settimana da comunicare (n.) | C4: 1
B5: Periodo della settimana | C5: =TEXT(INDEX(Turnazione!$B$6:$B$70,($C$4-1)*5+1),"dd/mm/yyyy")&" - "&TEXT(INDEX(Turnazione!$B$6:$B$70,($C$4-1)*5+5),"dd/mm/yyyy")
B6: Comunicazione da inviare entro | C6: =TEXT(INDEX(Turnazione!$B$6:$B$70,($C$4-1)*5+1)-4,"dddd dd/mm/yyyy")
B8: Giorno | C8: Data | D8: Conducente | E8: Note sul turno
B9: =INDEX(Turnazione!$C$6:$C$70,($C$4-1)*5+1) | C9: =TEXT(INDEX(Turnazione!$B$6:$B$70,($C$4-1)*5+1),"dd/mm/yyyy") | D9: =INDEX(Turnazione!$F$6:$F$70,($C$4-1)*5+1) | E9: =INDEX(Calcoli!$Y$6:$Y$70,($C$4-1)*5+1)
B10: =INDEX(Turnazione!$C$6:$C$70,($C$4-1)*5+2) | C10: =TEXT(INDEX(Turnazione!$B$6:$B$70,($C$4-1)*5+2),"dd/mm/yyyy") | D10: =INDEX(Turnazione!$F$6:$F$70,($C$4-1)*5+2) | E10: =INDEX(Calcoli!$Y$6:$Y$70,($C$4-1)*5+2)
B11: =INDEX(Turnazione!$C$6:$C$70,($C$4-1)*5+3) | C11: =TEXT(INDEX(Turnazione!$B$6:$B$70,($C$4-1)*5+3),"dd/mm/yyyy") | D11: =INDEX(Turnazione!$F$6:$F$70,($C$4-1)*5+3) | E11: =INDEX(Calcoli!$Y$6:$Y$70,($C$4-1)*5+3)
B12: =INDEX(Turnazione!$C$6:$C$70,($C$4-1)*5+4) | C12: =TEXT(INDEX(Turnazione!$B$6:$B$70,($C$4-1)*5+4),"dd/mm/yyyy") | D12: =INDEX(Turnazione!$F$6:$F$70,($C$4-1)*5+4) | E12: =INDEX(Calcoli!$Y$6:$Y$70,($C$4-1)*5+4)
B13: =INDEX(Turnazione!$C$6:$C$70,($C$4-1)*5+5) | C13: =TEXT(INDEX(Turnazione!$B$6:$B$70,($C$4-1)*5+5),"dd/mm/yyyy") | D13: =INDEX(Turnazione!$F$6:$F$70,($C$4-1)*5+5) | E13: =INDEX(Calcoli!$Y$6:$Y$70,($C$4-1)*5+5)
B15: TESTO PRONTO DA INVIARE
B16: ="Servizio auto Trinitapoli → Foggia → Trinitapoli"&CHAR(10)&"Turnazione settimana n. "&$C$4&" ("&$C$5&")"&CHAR(10)&CHAR(10)&$B9&" - "&$C9&": "&$D9&IF($E9="",""," ("&$E9&")")&CHAR(10)&$B10&" - "&$C10&": "&$D10&IF($E10="",""," ("&$E10&")")&CHAR(10)&$B11&" - "&$C11&": "&$D11&IF($E11="",""," ("&$E11&")")&CHAR(10)&$B12&" - "&$C12&": "&$D12&IF($E12="",""," ("&$E12&")")&CHAR(10)&$B13&" - "&$C13&": "&$D13&IF($E13="",""," ("&$E13&")")&CHAR(10)&""

Sheet Riepilogo
A1: RIEPILOGO PER PARTECIPANTE
A2: Conteggi sull'intero periodo del servizio (13 settimane)
A5: Partecipante | B5: Turni ordinari | C5: Doppi turni (sostituzioni) | D5: Recuperi effettuati | E5: Totale guide | F5: Turni saltati non recuperabili | G5: Turni saltati da recuperare | H5: Recuperi ancora da saldare
A6: =Partecipanti!$B$5 | B6: =COUNTIFS(Turnazione!$F$6:$F$70,$A6,Turnazione!$G$6:$G$70,"Ordinario") | C6: =COUNTIFS(Turnazione!$F$6:$F$70,$A6,Turnazione!$G$6:$G$70,"Sostituzione (doppio turno)") | D6: =COUNTIFS(Turnazione!$F$6:$F$70,$A6,Turnazione!$G$6:$G$70,"Recupero") | E6: =SUM($B6:$D6) | F6: =COUNTIFS(Calcoli!$C$6:$C$70,$A6,Calcoli!$E$6:$E$70,1,Calcoli!$F$6:$F$70,0) | G6: =COUNTIFS(Calcoli!$C$6:$C$70,$A6,Calcoli!$F$6:$F$70,1) | H6: =MAX(0,$G6-$D6)
A7: =Partecipanti!$B$6 | B7: =COUNTIFS(Turnazione!$F$6:$F$70,$A7,Turnazione!$G$6:$G$70,"Ordinario") | C7: =COUNTIFS(Turnazione!$F$6:$F$70,$A7,Turnazione!$G$6:$G$70,"Sostituzione (doppio turno)") | D7: =COUNTIFS(Turnazione!$F$6:$F$70,$A7,Turnazione!$G$6:$G$70,"Recupero") | E7: =SUM($B7:$D7) | F7: =COUNTIFS(Calcoli!$C$6:$C$70,$A7,Calcoli!$E$6:$E$70,1,Calcoli!$F$6:$F$70,0) | G7: =COUNTIFS(Calcoli!$C$6:$C$70,$A7,Calcoli!$F$6:$F$70,1) | H7: =MAX(0,$G7-$D7)
A8: =Partecipanti!$B$7 | B8: =COUNTIFS(Turnazione!$F$6:$F$70,$A8,Turnazione!$G$6:$G$70,"Ordinario") | C8: =COUNTIFS(Turnazione!$F$6:$F$70,$A8,Turnazione!$G$6:$G$70,"Sostituzione (doppio turno)") | D8: =COUNTIFS(Turnazione!$F$6:$F$70,$A8,Turnazione!$G$6:$G$70,"Recupero") | E8: =SUM($B8:$D8) | F8: =COUNTIFS(Calcoli!$C$6:$C$70,$A8,Calcoli!$E$6:$E$70,1,Calcoli!$F$6:$F$70,0) | G8: =COUNTIFS(Calcoli!$C$6:$C$70,$A8,Calcoli!$F$6:$F$70,1) | H8: =MAX(0,$G8-$D8)
A9: =Partecipanti!$B$8 | B9: =COUNTIFS(Turnazione!$F$6:$F$70,$A9,Turnazione!$G$6:$G$70,"Ordinario") | C9: =COUNTIFS(Turnazione!$F$6:$F$70,$A9,Turnazione!$G$6:$G$70,"Sostituzione (doppio turno)") | D9: =COUNTIFS(Turnazione!$F$6:$F$70,$A9,Turnazione!$G$6:$G$70,"Recupero") | E9: =SUM($B9:$D9) | F9: =COUNTIFS(Calcoli!$C$6:$C$70,$A9,Calcoli!$E$6:$E$70,1,Calcoli!$F$6:$F$70,0) | G9: =COUNTIFS(Calcoli!$C$6:$C$70,$A9,Calcoli!$F$6:$F$70,1) | H9: =MAX(0,$G9-$D9)
A10: =Partecipanti!$B$9 | B10: =COUNTIFS(Turnazione!$F$6:$F$70,$A10,Turnazione!$G$6:$G$70,"Ordinario") | C10: =COUNTIFS(Turnazione!$F$6:$F$70,$A10,Turnazione!$G$6:$G$70,"Sostituzione (doppio turno)") | D10: =COUNTIFS(Turnazione!$F$6:$F$70,$A10,Turnazione!$G$6:$G$70,"Recupero") | E10: =SUM($B10:$D10) | F10: =COUNTIFS(Calcoli!$C$6:$C$70,$A10,Calcoli!$E$6:$E$70,1,Calcoli!$F$6:$F$70,0) | G10: =COUNTIFS(Calcoli!$C$6:$C$70,$A10,Calcoli!$F$6:$F$70,1) | H10: =MAX(0,$G10-$D10)
A11: TOTALE | B11: =SUM(B6:B10) | C11: =SUM(C6:C10) | D11: =SUM(D6:D10) | E11: =SUM(E6:E10) | F11: =SUM(F6:F10) | G11: =SUM(G6:G10) | H11: =SUM(H6:H10)
A13: Come leggere il riepilogo
A14: Totale guide | B14: Numero di volte in cui la persona prende effettivamente la macchina.
A15: Turni saltati non recuperabili | B15: Turni persi per licenza o attività esterna di settimana intera: non vanno recuperati (R1, R2).
A16: Turni saltati da recuperare | B16: Turni persi per altri motivi: generano un recupero nella settimana successiva (R3).
A17: Recuperi ancora da saldare | B17: Recuperi maturati e non ancora effettuati, di norma perché la persona era assente anche nella settimana del recupero (R7): vanno riprogrammati.

Sheet Calcoli
A1: Foglio di appoggio - non modificare
A5: Sett. | B5: Data | C5: Titolare | D5: Tipo assenza titolare | E5: Titolare assente | F5: Recuperabile | G5: Disp. Nicola | H5: Disp. Stefano | I5: Disp. Rocco | J5: Disp. Giuseppe | K5: Disp. Savino | L5: Recupero da | M5: Recupero attivo | N5: Punt. Nicola | O5: Punt. Stefano | P5: Punt. Rocco | Q5: Punt. Giuseppe | R5: Punt. Savino | S5: Sostituto | T5: Sostituto recuperabile | U5: Conducente effettivo | V5: Tipo turno | W5: A riposo | X5: Motivo variazione | Y5: Nota sintetica | AB5: Inizio servizio
A6: 1 | B6: 46293 | C6: =Partecipanti!$B$5 | D6: =IF(COUNTIFS(A_PERS,$C6,A_SETT,$A6,A_TIPO,"Licenza - settimana intera")>0,"Licenza - settimana intera",IF(COUNTIFS(A_PERS,$C6,A_SETT,$A6,A_TIPO,"Attività esterna - settimana intera")>0,"Attività esterna - settimana intera",IF(COUNTIFS(A_PERS,$C6,A_DATA,$B6)>0,INDEX(A_TIPO,MATCH(1,INDEX((A_PERS=$C6)*(A_DATA=$B6),0),0)),""))) | E6: =IF($D6="",0,1) | F6: =IF($E6=0,0,IF(OR($D6="Licenza - settimana intera",$D6="Attività esterna - settimana intera"),0,1)) | G6: =IF(COUNTIFS(A_PERS,Partecipanti!$B$5,A_DATA,$B6)+COUNTIFS(A_PERS,Partecipanti!$B$5,A_SETT,$A6,A_TIPO,"Licenza - settimana intera")+COUNTIFS(A_PERS,Partecipanti!$B$5,A_SETT,$A6,A_TIPO,"Attività esterna - settimana intera")>0,0,1) | H6: =IF(COUNTIFS(A_PERS,Partecipanti!$B$6,A_DATA,$B6)+COUNTIFS(A_PERS,Partecipanti!$B$6,A_SETT,$A6,A_TIPO,"Licenza - settimana intera")+COUNTIFS(A_PERS,Partecipanti!$B$6,A_SETT,$A6,A_TIPO,"Attività esterna - settimana intera")>0,0,1) | I6: =IF(COUNTIFS(A_PERS,Partecipanti!$B$7,A_DATA,$B6)+COUNTIFS(A_PERS,Partecipanti!$B$7,A_SETT,$A6,A_TIPO,"Licenza - settimana intera")+COUNTIFS(A_PERS,Partecipanti!$B$7,A_SETT,$A6,A_TIPO,"Attività esterna - settimana intera")>0,0,1) | J6: =IF(COUNTIFS(A_PERS,Partecipanti!$B$8,A_DATA,$B6)+COUNTIFS(A_PERS,Partecipanti!$B$8,A_SETT,$A6,A_TIPO,"Licenza - settimana intera")+COUNTIFS(A_PERS,Partecipanti!$B$8,A_SETT,$A6,A_TIPO,"Attività esterna - settimana intera")>0,0,1) | K6: =IF(COUNTIFS(A_PERS,Partecipanti!$B$9,A_DATA,$B6)+COUNTIFS(A_PERS,Partecipanti!$B$9,A_SETT,$A6,A_TIPO,"Licenza - settimana intera")+COUNTIFS(A_PERS,Partecipanti!$B$9,A_SETT,$A6,A_TIPO,"Attività esterna - settimana intera")>0,0,1) | M6: =IF($L6="",0,IF(INDEX($G6:$K6,MATCH($L6,Partecipanti!$B$5:$B$9,0))=1,1,0)) | N6: =IF($G6=0,100000,IF(Partecipanti!$B$5=$C6,100000,0*100+MOD(1-MATCH($C6,Partecipanti!$B$5:$B$9,0)-1,5))) | O6: =IF($H6=0,100000,IF(Partecipanti!$B$6=$C6,100000,0*100+MOD(2-MATCH($C6,Partecipanti!$B$5:$B$9,0)-1,5))) | P6: =IF($I6=0,100000,IF(Partecipanti!$B$7=$C6,100000,0*100+MOD(3-MATCH($C6,Partecipanti!$B$5:$B$9,0)-1,5))) | Q6: =IF($J6=0,100000,IF(Partecipanti!$B$8=$C6,100000,0*100+MOD(4-MATCH($C6,Partecipanti!$B$5:$B$9,0)-1,5))) | R6: =IF($K6=0,100000,IF(Partecipanti!$B$9=$C6,100000,0*100+MOD(5-MATCH($C6,Partecipanti!$B$5:$B$9,0)-1,5))) | S6: =IF(OR($E6=0,$M6=1),"",IF(MIN($N6:$R6)>=100000,"DA ASSEGNARE",INDEX(Partecipanti!$B$5:$B$9,MATCH(MIN($N6:$R6),$N6:$R6,0)))) | T6: =IF(AND($F6=1,$S6<>"",$S6<>"DA ASSEGNARE"),$S6,"") | U6: =IF($M6=1,$L6,IF($E6=0,$C6,$S6)) | V6: =IF($M6=1,"Recupero",IF($E6=0,"Ordinario",IF($S6="DA ASSEGNARE","DA ASSEGNARE","Sostituzione (doppio turno)"))) | W6: =IF(OR($M6=1,$E6=1),$C6,"") | X6: =IF($M6=1,$L6&" recupera il turno saltato nella settimana "&($A6-1)&"; "&$C6&" a riposo compensativo",IF($E6=1,$C6&" assente ("&$D6&")"&IF($S6="DA ASSEGNARE","; nessun sostituto disponibile","; sostituisce "&$S6&" con doppio turno")&IF($F6=1,"; turno da recuperare nella settimana "&($A6+1),"; turno non da recuperare"),"")) | Y6: =IF($M6=1,"recupera il turno saltato nella settimana "&($A6-1)&", "&$C6&" a riposo",IF($E6=1,IF($S6="DA ASSEGNARE","turno da assegnare: "&$C6&" assente","in sostituzione di "&$C6&", doppio turno"),"")) | AB6: 46293 | AC6: numero settimane
A7: 1 | B7: 46294 | C7: =Partecipanti!$B$6 | D7: =IF(COUNTIFS(A_PERS,$C7,A_SETT,$A7,A_TIPO,"Licenza - settimana intera")>0,"Licenza - settimana intera",IF(COUNTIFS(A_PERS,$C7,A_SETT,$A7,A_TIPO,"Attività esterna - settimana intera")>0,"Attività esterna - settimana intera",IF(COUNTIFS(A_PERS,$C7,A_DATA,$B7)>0,INDEX(A_TIPO,MATCH(1,INDEX((A_PERS=$C7)*(A_DATA=$B7),0),0)),""))) | E7: =IF($D7="",0,1) | F7: =IF($E7=0,0,IF(OR($D7="Licenza - settimana intera",$D7="Attività esterna - settimana intera"),0,1)) | G7: =IF(COUNTIFS(A_PERS,Partecipanti!$B$5,A_DATA,$B7)+COUNTIFS(A_PERS,Partecipanti!$B$5,A_SETT,$A7,A_TIPO,"Licenza - settimana intera")+COUNTIFS(A_PERS,Partecipanti!$B$5,A_SETT,$A7,A_TIPO,"Attività esterna - settimana intera")>0,0,1) | H7: =IF(COUNTIFS(A_PERS,Partecipanti!$B$6,A_DATA,$B7)+COUNTIFS(A_PERS,Partecipanti!$B$6,A_SETT,$A7,A_TIPO,"Licenza - settimana intera")+COUNTIFS(A_PERS,Partecipanti!$B$6,A_SETT,$A7,A_TIPO,"Attività esterna - settimana intera")>0,0,1) | I7: =IF(COUNTIFS(A_PERS,Partecipanti!$B$7,A_DATA,$B7)+COUNTIFS(A_PERS,Partecipanti!$B$7,A_SETT,$A7,A_TIPO,"Licenza - settimana intera")+COUNTIFS(A_PERS,Partecipanti!$B$7,A_SETT,$A7,A_TIPO,"Attività esterna - settimana intera")>0,0,1) | J7: =IF(COUNTIFS(A_PERS,Partecipanti!$B$8,A_DATA,$B7)+COUNTIFS(A_PERS,Partecipanti!$B$8,A_SETT,$A7,A_TIPO,"Licenza - settimana intera")+COUNTIFS(A_PERS,Partecipanti!$B$8,A_SETT,$A7,A_TIPO,"Attività esterna - settimana intera")>0,0,1) | K7: =IF(COUNTIFS(A_PERS,Partecipanti!$B$9,A_DATA,$B7)+COUNTIFS(A_PERS,Partecipanti!$B$9,A_SETT,$A7,A_TIPO,"Licenza - settimana intera")+COUNTIFS(A_PERS,Partecipanti!$B$9,A_SETT,$A7,A_TIPO,"Attività esterna - settimana intera")>0,0,1) | M7: =IF($L7="",0,IF(INDEX($G7:$K7,MATCH($L7,Partecipanti!$B$5:$B$9,0))=1,1,0)) | N7: =IF($G7=0,100000,IF(Partecipanti!$B$5=$C7,100000,COUNTIF($S$6:$S6,Partecipanti!$B$5)*100+MOD(1-MATCH($C7,Partecipanti!$B$5:$B$9,0)-1,5))) | O7: =IF($H7=0,100000,IF(Partecipanti!$B$6=$C7,100000,COUNTIF($S$6:$S6,Partecipanti!$B$6)*100+MOD(2-MATCH($C7,Partecipanti!$B$5:$B$9,0)-1,5))) | P7: =IF($I7=0,100000,IF(Partecipanti!$B$7=$C7,100000,COUNTIF($S$6:$S6,Partecipanti!$B$7)*100+MOD(3-MATCH($C7,Partecipanti!$B$5:$B$9,0)-1,5))) | Q7: =IF($J7=0,100000,IF(Partecipanti!$B$8=$C7,100000,COUNTIF($S$6:$S6,Partecipanti!$B$8)*100+MOD(4-MATCH($C7,Partecipanti!$B$5:$B$9,0)-1,5))) | R7: =IF($K7=0,100000,IF(Partecipanti!$B$9=$C7,100000,COUNTIF($S$6:$S6,Partecipanti!$B$9)*100+MOD(5-MATCH($C7,Partecipanti!$B$5:$B$9,0)-1,5))) | S7: =IF(OR($E7=0,$M7=1),"",IF(MIN($N7:$R7)>=100000,"DA ASSEGNARE",INDEX(Partecipanti!$B$5:$B$9,MATCH(MIN($N7:$R7),$N7:$R7,0)))) | T7: =IF(AND($F7=1,$S7<>"",$S7<>"DA ASSEGNARE"),$S7,"") | U7: =IF($M7=1,$L7,IF($E7=0,$C7,$S7)) | V7: =IF($M7=1,"Recupero",IF($E7=0,"Ordinario",IF($S7="DA ASSEGNARE","DA ASSEGNARE","Sostituzione (doppio turno)"))) | W7: =IF(OR($M7=1,$E7=1),$C7,"") | X7: =IF($M7=1,$L7&" recupera il turno saltato nella settimana "&($A7-1)&"; "&$C7&" a riposo compensativo",IF($E7=1,$C7&" assente ("&$D7&")"&IF($S7="DA ASSEGNARE","; nessun sostituto disponibile","; sostituisce "&$S7&" con doppio turno")&IF($F7=1,"; turno da recuperare nella settimana "&($A7+1),"; turno non da recuperare"),"")) | Y7: =IF($M7=1,"recupera il turno saltato nella settimana "&($A7-1)&", "&$C7&" a riposo",IF($E7=1,IF($S7="DA ASSEGNARE","turno da assegnare: "&$C7&" assente","in sostituzione di "&$C7&", doppio turno"),"")) | AB7: 13
A8: 1 | B8: 46295 | C8: =Partecipanti!$B$7 | D8: =IF(COUNTIFS(A_PERS,$C8,A_SETT,$A8,A_TIPO,"Licenza - settimana intera")>0,"Licenza - settimana intera",IF(COUNTIFS(A_PERS,$C8,A_SETT,$A8,A_TIPO,"Attività esterna - settimana intera")>0,"Attività esterna - settimana intera",IF(COUNTIFS(A_PERS,$C8,A_DATA,$B8)>0,INDEX(A_TIPO,MATCH(1,INDEX((A_PERS=$C8)*(A_DATA=$B8),0),0)),""))) | E8: =IF($D8="",0,1) | F8: =IF($E8=0,0,IF(OR($D8="Licenza - settimana intera",$D8="Attività esterna - settimana intera"),0,1)) | G8: =IF(COUNTIFS(A_PERS,Partecipanti!$B$5,A_DATA,$B8)+COUNTIFS(A_PERS,Partecipanti!$B$5,A_SETT,$A8,A_TIPO,"Licenza - settimana intera")+COUNTIFS(A_PERS,Partecipanti!$B$5,A_SETT,$A8,A_TIPO,"Attività esterna - settimana intera")>0,0,1) | H8: =IF(COUNTIFS(A_PERS,Partecipanti!$B$6,A_DATA,$B8)+COUNTIFS(A_PERS,Partecipanti!$B$6,A_SETT,$A8,A_TIPO,"Licenza - settimana intera")+COUNTIFS(A_PERS,Partecipanti!$B$6,A_SETT,$A8,A_TIPO,"Attività esterna - settimana intera")>0,0,1) | I8: =IF(COUNTIFS(A_PERS,Partecipanti!$B$7,A_DATA,$B8)+COUNTIFS(A_PERS,Partecipanti!$B$7,A_SETT,$A8,A_TIPO,"Licenza - settimana intera")+COUNTIFS(A_PERS,Partecipanti!$B$7,A_SETT,$A8,A_TIPO,"Attività esterna - settimana intera")>0,0,1) | J8: =IF(COUNTIFS(A_PERS,Partecipanti!$B$8,A_DATA,$B8)+COUNTIFS(A_PERS,Partecipanti!$B$8,A_SETT,$A8,A_TIPO,"Licenza - settimana intera")+COUNTIFS(A_PERS,Partecipanti!$B$8,A_SETT,$A8,A_TIPO,"Attività esterna - settimana intera")>0,0,1) | K8: =IF(COUNTIFS(A_PERS,Partecipanti!$B$9,A_DATA,$B8)+COUNTIFS(A_PERS,Partecipanti!$B$9,A_SETT,$A8,A_TIPO,"Licenza - settimana intera")+COUNTIFS(A_PERS,Partecipanti!$B$9,A_SETT,$A8,A_TIPO,"Attività esterna - settimana intera")>0,0,1) | M8: =IF($L8="",0,IF(INDEX($G8:$K8,MATCH($L8,Partecipanti!$B$5:$B$9,0))=1,1,0)) | N8: =IF($G8=0,100000,IF(Partecipanti!$B$5=$C8,100000,COUNTIF($S$6:$S7,Partecipanti!$B$5)*100+MOD(1-MATCH($C8,Partecipanti!$B$5:$B$9,0)-1,5))) | O8: =IF($H8=0,100000,IF(Partecipanti!$B$6=$C8,100000,COUNTIF($S$6:$S7,Partecipanti!$B$6)*100+MOD(2-MATCH($C8,Partecipanti!$B$5:$B$9,0)-1,5))) | P8: =IF($I8=0,100000,IF(Partecipanti!$B$7=$C8,100000,COUNTIF($S$6:$S7,Partecipanti!$B$7)*100+MOD(3-MATCH($C8,Partecipanti!$B$5:$B$9,0)-1,5))) | Q8: =IF($J8=0,100000,IF(Partecipanti!$B$8=$C8,100000,COUNTIF($S$6:$S7,Partecipanti!$B$8)*100+MOD(4-MATCH($C8,Partecipanti!$B$5:$B$9,0)-1,5))) | R8: =IF($K8=0,100000,IF(Partecipanti!$B$9=$C8,100000,COUNTIF($S$6:$S7,Partecipanti!$B$9)*100+MOD(5-MATCH($C8,Partecipanti!$B$5:$B$9,0)-1,5))) | S8: =IF(OR($E8=0,$M8=1),"",IF(MIN($N8:$R8)>=100000,"DA ASSEGNARE",INDEX(Partecipanti!$B$5:$B$9,MATCH(MIN($N8:$R8),$N8:$R8,0)))) | T8: =IF(AND($F8=1,$S8<>"",$S8<>"DA ASSEGNARE"),$S8,"") | U8: =IF($M8=1,$L8,IF($E8=0,$C8,$S8)) | V8: =IF($M8=1,"Recupero",IF($E8=0,"Ordinario",IF($S8="DA ASSEGNARE","DA ASSEGNARE","Sostituzione (doppio turno)"))) | W8: =IF(OR($M8=1,$E8=1),$C8,"") | X8: =IF($M8=1,$L8&" recupera il turno saltato nella settimana "&($A8-1)&"; "&$C8&" a riposo compensativo",IF($E8=1,$C8&" assente ("&$D8&")"&IF($S8="DA ASSEGNARE","; nessun sostituto disponibile","; sostituisce "&$S8&" con doppio turno")&IF($F8=1,"; turno da recuperare nella settimana "&($A8+1),"; turno non da recuperare"),"")) | Y8: =IF($M8=1,"recupera il turno saltato nella settimana "&($A8-1)&", "&$C8&" a riposo",IF($E8=1,IF($S8="DA ASSEGNARE","turno da assegnare: "&$C8&" assente","in sostituzione di "&$C8&", doppio turno"),""))
A9: 1 | B9: 46296 | C9: =Partecipanti!$B$8 | D9: =IF(COUNTIFS(A_PERS,$C9,A_SETT,$A9,A_TIPO,"Licenza - settimana intera")>0,"Licenza - settimana intera",IF(COUNTIFS(A_PERS,$C9,A_SETT,$A9,A_TIPO,"Attività esterna - settimana intera")>0,"Attività esterna - settimana intera",IF(COUNTIFS(A_PERS,$C9,A_DATA,$B9)>0,INDEX(A_TIPO,MATCH(1,INDEX((A_PERS=$C9)*(A_DATA=$B9),0),0)),""))) | E9: =IF($D9="",0,1) | F9: =IF($E9=0,0,IF(OR($D9="Licenza - settimana intera",$D9="Attività esterna - settimana intera"),0,1)) | G9: =IF(COUNTIFS(A_PERS,Partecipanti!$B$5,A_DATA,$B9)+COUNTIFS(A_PERS,Partecipanti!$B$5,A_SETT,$A9,A_TIPO,"Licenza - settimana intera")+COUNTIFS(A_PERS,Partecipanti!$B$5,A_SETT,$A9,A_TIPO,"Attività esterna - settimana intera")>0,0,1) | H9: =IF(COUNTIFS(A_PERS,Partecipanti!$B$6,A_DATA,$B9)+COUNTIFS(A_PERS,Partecipanti!$B$6,A_SETT,$A9,A_TIPO,"Licenza - settimana intera")+COUNTIFS(A_PERS,Partecipanti!$B$6,A_SETT,$A9,A_TIPO,"Attività esterna - settimana intera")>0,0,1) | I9: =IF(COUNTIFS(A_PERS,Partecipanti!$B$7,A_DATA,$B9)+COUNTIFS(A_PERS,Partecipanti!$B$7,A_SETT,$A9,A_TIPO,"Licenza - settimana intera")+COUNTIFS(A_PERS,Partecipanti!$B$7,A_SETT,$A9,A_TIPO,"Attività esterna - settimana intera")>0,0,1) | J9: =IF(COUNTIFS(A_PERS,Partecipanti!$B$8,A_DATA,$B9)+COUNTIFS(A_PERS,Partecipanti!$B$8,A_SETT,$A9,A_TIPO,"Licenza - settimana intera")+COUNTIFS(A_PERS,Partecipanti!$B$8,A_SETT,$A9,A_TIPO,"Attività esterna - settimana intera")>0,0,1) | K9: =IF(COUNTIFS(A_PERS,Partecipanti!$B$9,A_DATA,$B9)+COUNTIFS(A_PERS,Partecipanti!$B$9,A_SETT,$A9,A_TIPO,"Licenza - settimana intera")+COUNTIFS(A_PERS,Partecipanti!$B$9,A_SETT,$A9,A_TIPO,"Attività esterna - settimana intera")>0,0,1) | M9: =IF($L9="",0,IF(INDEX($G9:$K9,MATCH($L9,Partecipanti!$B$5:$B$9,0))=1,1,0)) | N9: =IF($G9=0,100000,IF(Partecipanti!$B$5=$C9,100000,COUNTIF($S$6:$S8,Partecipanti!$B$5)*100+MOD(1-MATCH($C9,Partecipanti!$B$5:$B$9,0)-1,5))) | O9: =IF($H9=0,100000,IF(Partecipanti!$B$6=$C9,100000,COUNTIF($S$6:$S8,Partecipanti!$B$6)*100+MOD(2-MATCH($C9,Partecipanti!$B$5:$B$9,0)-1,5))) | P9: =IF($I9=0,100000,IF(Partecipanti!$B$7=$C9,100000,COUNTIF($S$6:$S8,Partecipanti!$B$7)*100+MOD(3-MATCH($C9,Partecipanti!$B$5:$B$9,0)-1,5))) | Q9: =IF($J9=0,100000,IF(Partecipanti!$B$8=$C9,100000,COUNTIF($S$6:$S8,Partecipanti!$B$8)*100+MOD(4-MATCH($C9,Partecipanti!$B$5:$B$9,0)-1,5))) | R9: =IF($K9=0,100000,IF(Partecipanti!$B$9=$C9,100000,COUNTIF($S$6:$S8,Partecipanti!$B$9)*100+MOD(5-MATCH($C9,Partecipanti!$B$5:$B$9,0)-1,5))) | S9: =IF(OR($E9=0,$M9=1),"",IF(MIN($N9:$R9)>=100000,"DA ASSEGNARE",INDEX(Partecipanti!$B$5:$B$9,MATCH(MIN($N9:$R9),$N9:$R9,0)))) | T9: =IF(AND($F9=1,$S9<>"",$S9<>"DA ASSEGNARE"),$S9,"") | U9: =IF($M9=1,$L9,IF($E9=0,$C9,$S9)) | V9: =IF($M9=1,"Recupero",IF($E9=0,"Ordinario",IF($S9="DA ASSEGNARE","DA ASSEGNARE","Sostituzione (doppio turno)"))) | W9: =IF(OR($M9=1,$E9=1),$C9,"") | X9: =IF($M9=1,$L9&" recupera il turno saltato nella settimana "&($A9-1)&"; "&$C9&" a riposo compensativo",IF($E9=1,$C9&" assente ("&$D9&")"&IF($S9="DA ASSEGNARE","; nessun sostituto disponibile","; sostituisce "&$S9&" con doppio turno")&IF($F9=1,"; turno da recuperare nella settimana "&($A9+1),"; turno non da recuperare"),"")) | Y9: =IF($M9=1,"recupera il turno saltato nella settimana "&($A9-1)&", "&$C9&" a riposo",IF($E9=1,IF($S9="DA ASSEGNARE","turno da assegnare: "&$C9&" assente","in sostituzione di "&$C9&", doppio turno"),""))
A10: 1 | B10: 46297 | C10: =Partecipanti!$B$9 | D10: =IF(COUNTIFS(A_PERS,$C10,A_SETT,$A10,A_TIPO,"Licenza - settimana intera")>0,"Licenza - settimana intera",IF(COUNTIFS(A_PERS,$C10,A_SETT,$A10,A_TIPO,"Attività esterna - settimana intera")>0,"Attività esterna - settimana intera",IF(COUNTIFS(A_PERS,$C10,A_DATA,$B10)>0,INDEX(A_TIPO,MATCH(1,INDEX((A_PERS=$C10)*(A_DATA=$B10),0),0)),""))) | E10: =IF($D10="",0,1) | F10: =IF($E10=0,0,IF(OR($D10="Licenza - settimana intera",$D10="Attività esterna - settimana intera"),0,1)) | G10: =IF(COUNTIFS(A_PERS,Partecipanti!$B$5,A_DATA,$B10)+COUNTIFS(A_PERS,Partecipanti!$B$5,A_SETT,$A10,A_TIPO,"Licenza - settimana intera")+COUNTIFS(A_PERS,Partecipanti!$B$5,A_SETT,$A10,A_TIPO,"Attività esterna - settimana intera")>0,0,1) | H10: =IF(COUNTIFS(A_PERS,Partecipanti!$B$6,A_DATA,$B10)+COUNTIFS(A_PERS,Partecipanti!$B$6,A_SETT,$A10,A_TIPO,"Licenza - settimana intera")+COUNTIFS(A_PERS,Partecipanti!$B$6,A_SETT,$A10,A_TIPO,"Attività esterna - settimana intera")>0,0,1) | I10: =IF(COUNTIFS(A_PERS,Partecipanti!$B$7,A_DATA,$B10)+COUNTIFS(A_PERS,Partecipanti!$B$7,A_SETT,$A10,A_TIPO,"Licenza - settimana intera")+COUNTIFS(A_PERS,Partecipanti!$B$7,A_SETT,$A10,A_TIPO,"Attività esterna - settimana intera")>0,0,1) | J10: =IF(COUNTIFS(A_PERS,Partecipanti!$B$8,A_DATA,$B10)+COUNTIFS(A_PERS,Partecipanti!$B$8,A_SETT,$A10,A_TIPO,"Licenza - settimana intera")+COUNTIFS(A_PERS,Partecipanti!$B$8,A_SETT,$A10,A_TIPO,"Attività esterna - settimana intera")>0,0,1) | K10: =IF(COUNTIFS(A_PERS,Partecipanti!$B$9,A_DATA,$B10)+COUNTIFS(A_PERS,Partecipanti!$B$9,A_SETT,$A10,A_TIPO,"Licenza - settimana intera")+COUNTIFS(A_PERS,Partecipanti!$B$9,A_SETT,$A10,A_TIPO,"Attività esterna - settimana intera")>0,0,1) | M10: =IF($L10="",0,IF(INDEX($G10:$K10,MATCH($L10,Partecipanti!$B$5:$B$9,0))=1,1,0)) | N10: =IF($G10=0,100000,IF(Partecipanti!$B$5=$C10,100000,COUNTIF($S$6:$S9,Partecipanti!$B$5)*100+MOD(1-MATCH($C10,Partecipanti!$B$5:$B$9,0)-1,5))) | O10: =IF($H10=0,100000,IF(Partecipanti!$B$6=$C10,100000,COUNTIF($S$6:$S9,Partecipanti!$B$6)*100+MOD(2-MATCH($C10,Partecipanti!$B$5:$B$9,0)-1,5))) | P10: =IF($I10=0,100000,IF(Partecipanti!$B$7=$C10,100000,COUNTIF($S$6:$S9,Partecipanti!$B$7)*100+MOD(3-MATCH($C10,Partecipanti!$B$5:$B$9,0)-1,5))) | Q10: =IF($J10=0,100000,IF(Partecipanti!$B$8=$C10,100000,COUNTIF($S$6:$S9,Partecipanti!$B$8)*100+MOD(4-MATCH($C10,Partecipanti!$B$5:$B$9,0)-1,5))) | R10: =IF($K10=0,100000,IF(Partecipanti!$B$9=$C10,100000,COUNTIF($S$6:$S9,Partecipanti!$B$9)*100+MOD(5-MATCH($C10,Partecipanti!$B$5:$B$9,0)-1,5))) | S10: =IF(OR($E10=0,$M10=1),"",IF(MIN($N10:$R10)>=100000,"DA ASSEGNARE",INDEX(Partecipanti!$B$5:$B$9,MATCH(MIN($N10:$R10),$N10:$R10,0)))) | T10: =IF(AND($F10=1,$S10<>"",$S10<>"DA ASSEGNARE"),$S10,"") | U10: =IF($M10=1,$L10,IF($E10=0,$C10,$S10)) | V10: =IF($M10=1,"Recupero",IF($E10=0,"Ordinario",IF($S10="DA ASSEGNARE","DA ASSEGNARE","Sostituzione (doppio turno)"))) | W10: =IF(OR($M10=1,$E10=1),$C10,"") | X10: =IF($M10=1,$L10&" recupera il turno saltato nella settimana "&($A10-1)&"; "&$C10&" a riposo compensativo",IF($E10=1,$C10&" assente ("&$D10&")"&IF($S10="DA ASSEGNARE","; nessun sostituto disponibile","; sostituisce "&$S10&" con doppio turno")&IF($F10=1,"; turno da recuperare nella settimana "&($A10+1),"; turno non da recuperare"),"")) | Y10: =IF($M10=1,"recupera il turno saltato nella settimana "&($A10-1)&", "&$C10&" a riposo",IF($E10=1,IF($S10="DA ASSEGNARE","turno da assegnare: "&$C10&" assente","in sostituzione di "&$C10&", doppio turno"),""))
A11: 2 | B11: 46300 | C11: =Partecipanti!$B$5 | D11: =IF(COUNTIFS(A_PERS,$C11,A_SETT,$A11,A_TIPO,"Licenza - settimana intera")>0,"Licenza - settimana intera",IF(COUNTIFS(A_PERS,$C11,A_SETT,$A11,A_TIPO,"Attività esterna - settimana intera")>0,"Attività esterna - settimana intera",IF(COUNTIFS(A_PERS,$C11,A_DATA,$B11)>0,INDEX(A_TIPO,MATCH(1,INDEX((A_PERS=$C11)*(A_DATA=$B11),0),0)),""))) | E11: =IF($D11="",0,1) | F11: =IF($E11=0,0,IF(OR($D11="Licenza - settimana intera",$D11="Attività esterna - settimana intera"),0,1)) | G11: =IF(COUNTIFS(A_PERS,Partecipanti!$B$5,A_DATA,$B11)+COUNTIFS(A_PERS,Partecipanti!$B$5,A_SETT,$A11,A_TIPO,"Licenza - settimana intera")+COUNTIFS(A_PERS,Partecipanti!$B$5,A_SETT,$A11,A_TIPO,"Attività esterna - settimana intera")>0,0,1) | H11: =IF(COUNTIFS(A_PERS,Partecipanti!$B$6,A_DATA,$B11)+COUNTIFS(A_PERS,Partecipanti!$B$6,A_SETT,$A11,A_TIPO,"Licenza - settimana intera")+COUNTIFS(A_PERS,Partecipanti!$B$6,A_SETT,$A11,A_TIPO,"Attività esterna - settimana intera")>0,0,1) | I11: =IF(COUNTIFS(A_PERS,Partecipanti!$B$7,A_DATA,$B11)+COUNTIFS(A_PERS,Partecipanti!$B$7,A_SETT,$A11,A_TIPO,"Licenza - settimana intera")+COUNTIFS(A_PERS,Partecipanti!$B$7,A_SETT,$A11,A_TIPO,"Attività esterna - settimana intera")>0,0,1) | J11: =IF(COUNTIFS(A_PERS,Partecipanti!$B$8,A_DATA,$B11)+COUNTIFS(A_PERS,Partecipanti!$B$8,A_SETT,$A11,A_TIPO,"Licenza - settimana intera")+COUNTIFS(A_PERS,Partecipanti!$B$8,A_SETT,$A11,A_TIPO,"Attività esterna - settimana intera")>0,0,1) | K11: =IF(COUNTIFS(A_PERS,Partecipanti!$B$9,A_DATA,$B11)+COUNTIFS(A_PERS,Partecipanti!$B$9,A_SETT,$A11,A_TIPO,"Licenza - settimana intera")+COUNTIFS(A_PERS,Partecipanti!$B$9,A_SETT,$A11,A_TIPO,"Attività esterna - settimana intera")>0,0,1) | L11: =IFERROR(INDEX($C6:$C10,MATCH(1,INDEX(($T6:$T10=$C11)*1,0),0)),"") | M11: =IF($L11="",0,IF(INDEX($G11:$K11,MATCH($L11,Partecipanti!$B$5:$B$9,0))=1,1,0)) | N11: =IF($G11=0,100000,IF(Partecipanti!$B$5=$C11,100000,COUNTIF($S$6:$S10,Partecipanti!$B$5)*100+MOD(1-MATCH($C11,Partecipanti!$B$5:$B$9,0)-1,5))) | O11: =IF($H11=0,100000,IF(Partecipanti!$B$6=$C11,100000,COUNTIF($S$6:$S10,Partecipanti!$B$6)*100+MOD(2-MATCH($C11,Partecipanti!$B$5:$B$9,0)-1,5))) | P11: =IF($I11=0,100000,IF(Partecipanti!$B$7=$C11,100000,COUNTIF($S$6:$S10,Partecipanti!$B$7)*100+MOD(3-MATCH($C11,Partecipanti!$B$5:$B$9,0)-1,5))) | Q11: =IF($J11=0,100000,IF(Partecipanti!$B$8=$C11,100000,COUNTIF($S$6:$S10,Partecipanti!$B$8)*100+MOD(4-MATCH($C11,Partecipanti!$B$5:$B$9,0)-1,5))) | R11: =IF($K11=0,100000,IF(Partecipanti!$B$9=$C11,100000,COUNTIF($S$6:$S10,Partecipanti!$B$9)*100+MOD(5-MATCH($C11,Partecipanti!$B$5:$B$9,0)-1,5))) | S11: =IF(OR($E11=0,$M11=1),"",IF(MIN($N11:$R11)>=100000,"DA ASSEGNARE",INDEX(Partecipanti!$B$5:$B$9,MATCH(MIN($N11:$R11),$N11:$R11,0)))) | T11: =IF(AND($F11=1,$S11<>"",$S11<>"DA ASSEGNARE"),$S11,"") | U11: =IF($M11=1,$L11,IF($E11=0,$C11,$S11)) | V11: =IF($M11=1,"Recupero",IF($E11=0,"Ordinario",IF($S11="DA ASSEGNARE","DA ASSEGNARE","Sostituzione (doppio turno)"))) | W11: =IF(OR($M11=1,$E11=1),$C11,"") | X11: =IF($M11=1,$L11&" recupera il turno saltato nella settimana "&($A11-1)&"; "&$C11&" a riposo compensativo",IF($E11=1,$C11&" assente ("&$D11&")"&IF($S11="DA ASSEGNARE","; nessun sostituto disponibile","; sostituisce "&$S11&" con doppio turno")&IF($F11=1,"; turno da recuperare nella settimana "&($A11+1),"; turno non da recuperare"),"")) | Y11: =IF($M11=1,"recupera il turno saltato nella settimana "&($A11-1)&", "&$C11&" a riposo",IF($E11=1,IF($S11="DA ASSEGNARE","turno da assegnare: "&$C11&" assente","in sostituzione di "&$C11&", doppio turno"),""))
A12: 2 | B12: 46301 | C12: =Partecipanti!$B$6 | D12: =IF(COUNTIFS(A_PERS,$C12,A_SETT,$A12,A_TIPO,"Licenza - settimana intera")>0,"Licenza - settimana intera",IF(COUNTIFS(A_PERS,$C12,A_SETT,$A12,A_TIPO,"Attività esterna - settimana intera")>0,"Attività esterna - settimana intera",IF(COUNTIFS(A_PERS,$C12,A_DATA,$B12)>0,INDEX(A_TIPO,MATCH(1,INDEX((A_PERS=$C12)*(A_DATA=$B12),0),0)),""))) | E12: =IF($D12="",0,1) | F12: =IF($E12=0,0,IF(OR($D12="Licenza - settimana intera",$D12="Attività esterna - settimana intera"),0,1)) | G12: =IF(COUNTIFS(A_PERS,Partecipanti!$B$5,A_DATA,$B12)+COUNTIFS(A_PERS,Partecipanti!$B$5,A_SETT,$A12,A_TIPO,"Licenza - settimana intera")+COUNTIFS(A_PERS,Partecipanti!$B$5,A_SETT,$A12,A_TIPO,"Attività esterna - settimana intera")>0,0,1) | H12: =IF(COUNTIFS(A_PERS,Partecipanti!$B$6,A_DATA,$B12)+COUNTIFS(A_PERS,Partecipanti!$B$6,A_SETT,$A12,A_TIPO,"Licenza - settimana intera")+COUNTIFS(A_PERS,Partecipanti!$B$6,A_SETT,$A12,A_TIPO,"Attività esterna - settimana intera")>0,0,1) | I12: =IF(COUNTIFS(A_PERS,Partecipanti!$B$7,A_DATA,$B12)+COUNTIFS(A_PERS,Partecipanti!$B$7,A_SETT,$A12,A_TIPO,"Licenza - settimana intera")+COUNTIFS(A_PERS,Partecipanti!$B$7,A_SETT,$A12,A_TIPO,"Attività esterna - settimana intera")>0,0,1) | J12: =IF(COUNTIFS(A_PERS,Partecipanti!$B$8,A_DATA,$B12)+COUNTIFS(A_PERS,Partecipanti!$B$8,A_SETT,$A12,A_TIPO,"Licenza - settimana intera")+COUNTIFS(A_PERS,Partecipanti!$B$8,A_SETT,$A12,A_TIPO,"Attività esterna - settimana intera")>0,0,1) | K12: =IF(COUNTIFS(A_PERS,Partecipanti!$B$9,A_DATA,$B12)+COUNTIFS(A_PERS,Partecipanti!$B$9,A_SETT,$A12,A_TIPO,"Licenza - settimana intera")+COUNTIFS(A_PERS,Partecipanti!$B$9,A_SETT,$A12,A_TIPO,"Attività esterna - settimana intera")>0,0,1) | L12: =IFERROR(INDEX($C6:$C10,MATCH(1,INDEX(($T6:$T10=$C12)*1,0),0)),"") | M12: =IF($L12="",0,IF(INDEX($G12:$K12,MATCH($L12,Partecipanti!$B$5:$B$9,0))=1,1,0)) | N12: =IF($G12=0,100000,IF(Partecipanti!$B$5=$C12,100000,COUNTIF($S$6:$S11,Partecipanti!$B$5)*100+MOD(1-MATCH($C12,Partecipanti!$B$5:$B$9,0)-1,5))) | O12: =IF($H12=0,100000,IF(Partecipanti!$B$6=$C12,100000,COUNTIF($S$6:$S11,Partecipanti!$B$6)*100+MOD(2-MATCH($C12,Partecipanti!$B$5:$B$9,0)-1,5))) | P12: =IF($I12=0,100000,IF(Partecipanti!$B$7=$C12,100000,COUNTIF($S$6:$S11,Partecipanti!$B$7)*100+MOD(3-MATCH($C12,Partecipanti!$B$5:$B$9,0)-1,5))) | Q12: =IF($J12=0,100000,IF(Partecipanti!$B$8=$C12,100000,COUNTIF($S$6:$S11,Partecipanti!$B$8)*100+MOD(4-MATCH($C12,Partecipanti!$B$5:$B$9,0)-1,5))) | R12: =IF($K12=0,100000,IF(Partecipanti!$B$9=$C12,100000,COUNTIF($S$6:$S11,Partecipanti!$B$9)*100+MOD(5-MATCH($C12,Partecipanti!$B$5:$B$9,0)-1,5))) | S12: =IF(OR($E12=0,$M12=1),"",IF(MIN($N12:$R12)>=100000,"DA ASSEGNARE",INDEX(Partecipanti!$B$5:$B$9,MATCH(MIN($N12:$R12),$N12:$R12,0)))) | T12: =IF(AND($F12=1,$S12<>"",$S12<>"DA ASSEGNARE"),$S12,"") | U12: =IF($M12=1,$L12,IF($E12=0,$C12,$S12)) | V12: =IF($M12=1,"Recupero",IF($E12=0,"Ordinario",IF($S12="DA ASSEGNARE","DA ASSEGNARE","Sostituzione (doppio turno)"))) | W12: =IF(OR($M12=1,$E12=1),$C12,"") | X12: =IF($M12=1,$L12&" recupera il turno saltato nella settimana "&($A12-1)&"; "&$C12&" a riposo compensativo",IF($E12=1,$C12&" assente ("&$D12&")"&IF($S12="DA ASSEGNARE","; nessun sostituto disponibile","; sostituisce "&$S12&" con doppio turno")&IF($F12=1,"; turno da recuperare nella settimana "&($A12+1),"; turno non da recuperare"),"")) | Y12: =IF($M12=1,"recupera il turno saltato nella settimana "&($A12-1)&", "&$C12&" a riposo",IF($E12=1,IF($S12="DA ASSEGNARE","turno da assegnare: "&$C12&" assente","in sostituzione di "&$C12&", doppio turno"),""))
A13: 2 | B13: 46302 | C13: =Partecipanti!$B$7 | D13: =IF(COUNTIFS(A_PERS,$C13,A_SETT,$A13,A_TIPO,"Licenza - settimana intera")>0,"Licenza - settimana intera",IF(COUNTIFS(A_PERS,$C13,A_SETT,$A13,A_TIPO,"Attività esterna - settimana intera")>0,"Attività esterna - settimana intera",IF(COUNTIFS(A_PERS,$C13,A_DATA,$B13)>0,INDEX(A_TIPO,MATCH(1,INDEX((A_PERS=$C13)*(A_DATA=$B13),0),0)),""))) | E13: =IF($D13="",0,1) | F13: =IF($E13=0,0,IF(OR($D13="Licenza - settimana intera",$D13="Attività esterna - settimana intera"),0,1)) | G13: =IF(COUNTIFS(A_PERS,Partecipanti!$B$5,A_DATA,$B13)+COUNTIFS(A_PERS,Partecipanti!$B$5,A_SETT,$A13,A_TIPO,"Licenza - settimana intera")+COUNTIFS(A_PERS,Partecipanti!$B$5,A_SETT,$A13,A_TIPO,"Attività esterna - settimana intera")>0,0,1) | H13: =IF(COUNTIFS(A_PERS,Partecipanti!$B$6,A_DATA,$B13)+COUNTIFS(A_PERS,Partecipanti!$B$6,A_SETT,$A13,A_TIPO,"Licenza - settimana intera")+COUNTIFS(A_PERS,Partecipanti!$B$6,A_SETT,$A13,A_TIPO,"Attività esterna - settimana intera")>0,0,1) | I13: =IF(COUNTIFS(A_PERS,Partecipanti!$B$7,A_DATA,$B13)+COUNTIFS(A_PERS,Partecipanti!$B$7,A_SETT,$A13,A_TIPO,"Licenza - settimana intera")+COUNTIFS(A_PERS,Partecipanti!$B$7,A_SETT,$A13,A_TIPO,"Attività esterna - settimana intera")>0,0,1) | J13: =IF(COUNTIFS(A_PERS,Partecipanti!$B$8,A_DATA,$B13)+COUNTIFS(A_PERS,Partecipanti!$B$8,A_SETT,$A13,A_TIPO,"Licenza - settimana intera")+COUNTIFS(A_PERS,Partecipanti!$B$8,A_SETT,$A13,A_TIPO,"Attività esterna - settimana intera")>0,0,1) | K13: =IF(COUNTIFS(A_PERS,Partecipanti!$B$9,A_DATA,$B13)+COUNTIFS(A_PERS,Partecipanti!$B$9,A_SETT,$A13,A_TIPO,"Licenza - settimana intera")+COUNTIFS(A_PERS,Partecipanti!$B$9,A_SETT,$A13,A_TIPO,"Attività esterna - settimana intera")>0,0,1) | L13: =IFERROR(INDEX($C6:$C10,MATCH(1,INDEX(($T6:$T10=$C13)*1,0),0)),"") | M13: =IF($L13="",0,IF(INDEX($G13:$K13,MATCH($L13,Partecipanti!$B$5:$B$9,0))=1,1,0)) | N13: =IF($G13=0,100000,IF(Partecipanti!$B$5=$C13,100000,COUNTIF($S$6:$S12,Partecipanti!$B$5)*100+MOD(1-MATCH($C13,Partecipanti!$B$5:$B$9,0)-1,5))) | O13: =IF($H13=0,100000,IF(Partecipanti!$B$6=$C13,100000,COUNTIF($S$6:$S12,Partecipanti!$B$6)*100+MOD(2-MATCH($C13,Partecipanti!$B$5:$B$9,0)-1,5))) | P13: =IF($I13=0,100000,IF(Partecipanti!$B$7=$C13,100000,COUNTIF($S$6:$S12,Partecipanti!$B$7)*100+MOD(3-MATCH($C13,Partecipanti!$B$5:$B$9,0)-1,5))) | Q13: =IF($J13=0,100000,IF(Partecipanti!$B$8=$C13,100000,COUNTIF($S$6:$S12,Partecipanti!$B$8)*100+MOD(4-MATCH($C13,Partecipanti!$B$5:$B$9,0)-1,5))) | R13: =IF($K13=0,100000,IF(Partecipanti!$B$9=$C13,100000,COUNTIF($S$6:$S12,Partecipanti!$B$9)*100+MOD(5-MATCH($C13,Partecipanti!$B$5:$B$9,0)-1,5))) | S13: =IF(OR($E13=0,$M13=1),"",IF(MIN($N13:$R13)>=100000,"DA ASSEGNARE",INDEX(Partecipanti!$B$5:$B$9,MATCH(MIN($N13:$R13),$N13:$R13,0)))) | T13: =IF(AND($F13=1,$S13<>"",$S13<>"DA ASSEGNARE"),$S13,"") | U13: =IF($M13=1,$L13,IF($E13=0,$C13,$S13)) | V13: =IF($M13=1,"Recupero",IF($E13=0,"Ordinario",IF($S13="DA ASSEGNARE","DA ASSEGNARE","Sostituzione (doppio turno)"))) | W13: =IF(OR($M13=1,$E13=1),$C13,"") | X13: =IF($M13=1,$L13&" recupera il turno saltato nella settimana "&($A13-1)&"; "&$C13&" a riposo compensativo",IF($E13=1,$C13&" assente ("&$D13&")"&IF($S13="DA ASSEGNARE","; nessun sostituto disponibile","; sostituisce "&$S13&" con doppio turno")&IF($F13=1,"; turno da recuperare nella settimana "&($A13+1),"; turno non da recuperare"),"")) | Y13: =IF($M13=1,"recupera il turno saltato nella settimana "&($A13-1)&", "&$C13&" a riposo",IF($E13=1,IF($S13="DA ASSEGNARE","turno da assegnare: "&$C13&" assente","in sostituzione di "&$C13&", doppio turno"),""))
A14: 2 | B14: 46303 | C14: =Partecipanti!$B$8 | D14: =IF(COUNTIFS(A_PERS,$C14,A_SETT,$A14,A_TIPO,"Licenza - settimana intera")>0,"Licenza - settimana intera",IF(COUNTIFS(A_PERS,$C14,A_SETT,$A14,A_TIPO,"Attività esterna - settimana intera")>0,"Attività esterna - settimana intera",IF(COUNTIFS(A_PERS,$C14,A_DATA,$B14)>0,INDEX(A_TIPO,MATCH(1,INDEX((A_PERS=$C14)*(A_DATA=$B14),0),0)),""))) | E14: =IF($D14="",0,1) | F14: =IF($E14=0,0,IF(OR($D14="Licenza - settimana intera",$D14="Attività esterna - settimana intera"),0,1)) | G14: =IF(COUNTIFS(A_PERS,Partecipanti!$B$5,A_DATA,$B14)+COUNTIFS(A_PERS,Partecipanti!$B$5,A_SETT,$A14,A_TIPO,"Licenza - settimana intera")+COUNTIFS(A_PERS,Partecipanti!$B$5,A_SETT,$A14,A_TIPO,"Attività esterna - settimana intera")>0,0,1) | H14: =IF(COUNTIFS(A_PERS,Partecipanti!$B$6,A_DATA,$B14)+COUNTIFS(A_PERS,Partecipanti!$B$6,A_SETT,$A14,A_TIPO,"Licenza - settimana intera")+COUNTIFS(A_PERS,Partecipanti!$B$6,A_SETT,$A14,A_TIPO,"Attività esterna - settimana intera")>0,0,1) | I14: =IF(COUNTIFS(A_PERS,Partecipanti!$B$7,A_DATA,$B14)+COUNTIFS(A_PERS,Partecipanti!$B$7,A_SETT,$A14,A_TIPO,"Licenza - settimana intera")+COUNTIFS(A_PERS,Partecipanti!$B$7,A_SETT,$A14,A_TIPO,"Attività esterna - settimana intera")>0,0,1) | J14: =IF(COUNTIFS(A_PERS,Partecipanti!$B$8,A_DATA,$B14)+COUNTIFS(A_PERS,Partecipanti!$B$8,A_SETT,$A14,A_TIPO,"Licenza - settimana intera")+COUNTIFS(A_PERS,Partecipanti!$B$8,A_SETT,$A14,A_TIPO,"Attività esterna - settimana intera")>0,0,1) | K14: =IF(COUNTIFS(A_PERS,Partecipanti!$B$9,A_DATA,$B14)+COUNTIFS(A_PERS,Partecipanti!$B$9,A_SETT,$A14,A_TIPO,"Licenza - settimana intera")+COUNTIFS(A_PERS,Partecipanti!$B$9,A_SETT,$A14,A_TIPO,"Attività esterna - settimana intera")>0,0,1) | L14: =IFERROR(INDEX($C6:$C10,MATCH(1,INDEX(($T6:$T10=$C14)*1,0),0)),"") | M14: =IF($L14="",0,IF(INDEX($G14:$K14,MATCH($L14,Partecipanti!$B$5:$B$9,0))=1,1,0)) | N14: =IF($G14=0,100000,IF(Partecipanti!$B$5=$C14,100000,COUNTIF($S$6:$S13,Partecipanti!$B$5)*100+MOD(1-MATCH($C14,Partecipanti!$B$5:$B$9,0)-1,5))) | O14: =IF($H14=0,100000,IF(Partecipanti!$B$6=$C14,100000,COUNTIF($S$6:$S13,Partecipanti!$B$6)*100+MOD(2-MATCH($C14,Partecipanti!$B$5:$B$9,0)-1,5))) | P14: =IF($I14=0,100000,IF(Partecipanti!$B$7=$C14,100000,COUNTIF($S$6:$S13,Partecipanti!$B$7)*100+MOD(3-MATCH($C14,Partecipanti!$B$5:$B$9,0)-1,5))) | Q14: =IF($J14=0,100000,IF(Partecipanti!$B$8=$C14,100000,COUNTIF($S$6:$S13,Partecipanti!$B$8)*100+MOD(4-MATCH($C14,Partecipanti!$B$5:$B$9,0)-1,5))) | R14: =IF($K14=0,100000,IF(Partecipanti!$B$9=$C14,100000,COUNTIF($S$6:$S13,Partecipanti!$B$9)*100+MOD(5-MATCH($C14,Partecipanti!$B$5:$B$9,0)-1,5))) | S14: =IF(OR($E14=0,$M14=1),"",IF(MIN($N14:$R14)>=100000,"DA ASSEGNARE",INDEX(Partecipanti!$B$5:$B$9,MATCH(MIN($N14:$R14),$N14:$R14,0)))) | T14: =IF(AND($F14=1,$S14<>"",$S14<>"DA ASSEGNARE"),$S14,"") | U14: =IF($M14=1,$L14,IF($E14=0,$C14,$S14)) | V14: =IF($M14=1,"Recupero",IF($E14=0,"Ordinario",IF($S14="DA ASSEGNARE","DA ASSEGNARE","Sostituzione (doppio turno)"))) | W14: =IF(OR($M14=1,$E14=1),$C14,"") | X14: =IF($M14=1,$L14&" recupera il turno saltato nella settimana "&($A14-1)&"; "&$C14&" a riposo compensativo",IF($E14=1,$C14&" assente ("&$D14&")"&IF($S14="DA ASSEGNARE","; nessun sostituto disponibile","; sostituisce "&$S14&" con doppio turno")&IF($F14=1,"; turno da recuperare nella settimana "&($A14+1),"; turno non da recuperare"),"")) | Y14: =IF($M14=1,"recupera il turno saltato nella settimana "&($A14-1)&", "&$C14&" a riposo",IF($E14=1,IF($S14="DA ASSEGNARE","turno da assegnare: "&$C14&" assente","in sostituzione di "&$C14&", doppio turno"),""))
A15: 2 | B15: 46304 | C15: =Partecipanti!$B$9 | D15: =IF(COUNTIFS(A_PERS,$C15,A_SETT,$A15,A_TIPO,"Licenza - settimana intera")>0,"Licenza - settimana intera",IF(COUNTIFS(A_PERS,$C15,A_SETT,$A15,A_TIPO,"Attività esterna - settimana intera")>0,"Attività esterna - settimana intera",IF(COUNTIFS(A_PERS,$C15,A_DATA,$B15)>0,INDEX(A_TIPO,MATCH(1,INDEX((A_PERS=$C15)*(A_DATA=$B15),0),0)),""))) | E15: =IF($D15="",0,1) | F15: =IF($E15=0,0,IF(OR($D15="Licenza - settimana intera",$D15="Attività esterna - settimana intera"),0,1)) | G15: =IF(COUNTIFS(A_PERS,Partecipanti!$B$5,A_DATA,$B15)+COUNTIFS(A_PERS,Partecipanti!$B$5,A_SETT,$A15,A_TIPO,"Licenza - settimana intera")+COUNTIFS(A_PERS,Partecipanti!$B$5,A_SETT,$A15,A_TIPO,"Attività esterna - settimana intera")>0,0,1) | H15: =IF(COUNTIFS(A_PERS,Partecipanti!$B$6,A_DATA,$B15)+COUNTIFS(A_PERS,Partecipanti!$B$6,A_SETT,$A15,A_TIPO,"Licenza - settimana intera")+COUNTIFS(A_PERS,Partecipanti!$B$6,A_SETT,$A15,A_TIPO,"Attività esterna - settimana intera")>0,0,1) | I15: =IF(COUNTIFS(A_PERS,Partecipanti!$B$7,A_DATA,$B15)+COUNTIFS(A_PERS,Partecipanti!$B$7,A_SETT,$A15,A_TIPO,"Licenza - settimana intera")+COUNTIFS(A_PERS,Partecipanti!$B$7,A_SETT,$A15,A_TIPO,"Attività esterna - settimana intera")>0,0,1) | J15: =IF(COUNTIFS(A_PERS,Partecipanti!$B$8,A_DATA,$B15)+COUNTIFS(A_PERS,Partecipanti!$B$8,A_SETT,$A15,A_TIPO,"Licenza - settimana intera")+COUNTIFS(A_PERS,Partecipanti!$B$8,A_SETT,$A15,A_TIPO,"Attività esterna - settimana intera")>0,0,1) | K15: =IF(COUNTIFS(A_PERS,Partecipanti!$B$9,A_DATA,$B15)+COUNTIFS(A_PERS,Partecipanti!$B$9,A_SETT,$A15,A_TIPO,"Licenza - settimana intera")+COUNTIFS(A_PERS,Partecipanti!$B$9,A_SETT,$A15,A_TIPO,"Attività esterna - settimana intera")>0,0,1) | L15: =IFERROR(INDEX($C6:$C10,MATCH(1,INDEX(($T6:$T10=$C15)*1,0),0)),"") | M15: =IF($L15="",0,IF(INDEX($G15:$K15,MATCH($L15,Partecipanti!$B$5:$B$9,0))=1,1,0)) | N15: =IF($G15=0,100000,IF(Partecipanti!$B$5=$C15,100000,COUNTIF($S$6:$S14,Partecipanti!$B$5)*100+MOD(1-MATCH($C15,Partecipanti!$B$5:$B$9,0)-1,5))) | O15: =IF($H15=0,100000,IF(Partecipanti!$B$6=$C15,100000,COUNTIF($S$6:$S14,Partecipanti!$B$6)*100+MOD(2-MATCH($C15,Partecipanti!$B$5:$B$9,0)-1,5))) | P15: =IF($I15=0,100000,IF(Partecipanti!$B$7=$C15,100000,COUNTIF($S$6:$S14,Partecipanti!$B$7)*100+MOD(3-MATCH($C15,Partecipanti!$B$5:$B$9,0)-1,5))) | Q15: =IF($J15=0,100000,IF(Partecipanti!$B$8=$C15,100000,COUNTIF($S$6:$S14,Partecipanti!$B$8)*100+MOD(4-MATCH($C15,Partecipanti!$B$5:$B$9,0)-1,5))) | R15: =IF($K15=0,100000,IF(Partecipanti!$B$9=$C15,100000,COUNTIF($S$6:$S14,Partecipanti!$B$9)*100+MOD(5-MATCH($C15,Partecipanti!$B$5:$B$9,0)-1,5))) | S15: =IF(OR($E15=0,$M15=1),"",IF(MIN($N15:$R15)>=100000,"DA ASSEGNARE",INDEX(Partecipanti!$B$5:$B$9,MATCH(MIN($N15:$R15),$N15:$R15,0)))) | T15: =IF(AND($F15=1,$S15<>"",$S15<>"DA ASSEGNARE"),$S15,"") | U15: =IF($M15=1,$L15,IF($E15=0,$C15,$S15)) | V15: =IF($M15=1,"Recupero",IF($E15=0,"Ordinario",IF($S15="DA ASSEGNARE","DA ASSEGNARE","Sostituzione (doppio turno)"))) | W15: =IF(OR($M15=1,$E15=1),$C15,"") | X15: =IF($M15=1,$L15&" recupera il turno saltato nella settimana "&($A15-1)&"; "&$C15&" a riposo compensativo",IF($E15=1,$C15&" assente ("&$D15&")"&IF($S15="DA ASSEGNARE","; nessun sostituto disponibile","; sostituisce "&$S15&" con doppio turno")&IF($F15=1,"; turno da recuperare nella settimana "&($A15+1),"; turno non da recuperare"),"")) | Y15: =IF($M15=1,"recupera il turno saltato nella settimana "&($A15-1)&", "&$C15&" a riposo",IF($E15=1,IF($S15="DA ASSEGNARE","turno da assegnare: "&$C15&" assente","in sostituzione di "&$C15&", doppio turno"),""))
A16: 3 | B16: 46307 | C16: =Partecipanti!$B$5 | D16: =IF(COUNTIFS(A_PERS,$C16,A_SETT,$A16,A_TIPO,"Licenza - settimana intera")>0,"Licenza - settimana intera",IF(COUNTIFS(A_PERS,$C16,A_SETT,$A16,A_TIPO,"Attività esterna - settimana intera")>0,"Attività esterna - settimana intera",IF(COUNTIFS(A_PERS,$C16,A_DATA,$B16)>0,INDEX(A_TIPO,MATCH(1,INDEX((A_PERS=$C16)*(A_DATA=$B16),0),0)),""))) | E16: =IF($D16="",0,1) | F16: =IF($E16=0,0,IF(OR($D16="Licenza - settimana intera",$D16="Attività esterna - settimana intera"),0,1)) | G16: =IF(COUNTIFS(A_PERS,Partecipanti!$B$5,A_DATA,$B16)+COUNTIFS(A_PERS,Partecipanti!$B$5,A_SETT,$A16,A_TIPO,"Licenza - settimana intera")+COUNTIFS(A_PERS,Partecipanti!$B$5,A_SETT,$A16,A_TIPO,"Attività esterna - settimana intera")>0,0,1) | H16: =IF(COUNTIFS(A_PERS,Partecipanti!$B$6,A_DATA,$B16)+COUNTIFS(A_PERS,Partecipanti!$B$6,A_SETT,$A16,A_TIPO,"Licenza - settimana intera")+COUNTIFS(A_PERS,Partecipanti!$B$6,A_SETT,$A16,A_TIPO,"Attività esterna - settimana intera")>0,0,1) | I16: =IF(COUNTIFS(A_PERS,Partecipanti!$B$7,A_DATA,$B16)+COUNTIFS(A_PERS,Partecipanti!$B$7,A_SETT,$A16,A_TIPO,"Licenza - settimana intera")+COUNTIFS(A_PERS,Partecipanti!$B$7,A_SETT,$A16,A_TIPO,"Attività esterna - settimana intera")>0,0,1) | J16: =IF(COUNTIFS(A_PERS,Partecipanti!$B$8,A_DATA,$B16)+COUNTIFS(A_PERS,Partecipanti!$B$8,A_SETT,$A16,A_TIPO,"Licenza - settimana intera")+COUNTIFS(A_PERS,Partecipanti!$B$8,A_SETT,$A16,A_TIPO,"Attività esterna - settimana intera")>0,0,1) | K16: =IF(COUNTIFS(A_PERS,Partecipanti!$B$9,A_DATA,$B16)+COUNTIFS(A_PERS,Partecipanti!$B$9,A_SETT,$A16,A_TIPO,"Licenza - settimana intera")+COUNTIFS(A_PERS,Partecipanti!$B$9,A_SETT,$A16,A_TIPO,"Attività esterna - settimana intera")>0,0,1) | L16: =IFERROR(INDEX($C11:$C15,MATCH(1,INDEX(($T11:$T15=$C16)*1,0),0)),"") | M16: =IF($L16="",0,IF(INDEX($G16:$K16,MATCH($L16,Partecipanti!$B$5:$B$9,0))=1,1,0)) | N16: =IF($G16=0,100000,IF(Partecipanti!$B$5=$C16,100000,COUNTIF($S$6:$S15,Partecipanti!$B$5)*100+MOD(1-MATCH($C16,Partecipanti!$B$5:$B$9,0)-1,5))) | O16: =IF($H16=0,100000,IF(Partecipanti!$B$6=$C16,100000,COUNTIF($S$6:$S15,Partecipanti!$B$6)*100+MOD(2-MATCH($C16,Partecipanti!$B$5:$B$9,0)-1,5))) | P16: =IF($I16=0,100000,IF(Partecipanti!$B$7=$C16,100000,COUNTIF($S$6:$S15,Partecipanti!$B$7)*100+MOD(3-MATCH($C16,Partecipanti!$B$5:$B$9,0)-1,5))) | Q16: =IF($J16=0,100000,IF(Partecipanti!$B$8=$C16,100000,COUNTIF($S$6:$S15,Partecipanti!$B$8)*100+MOD(4-MATCH($C16,Partecipanti!$B$5:$B$9,0)-1,5))) | R16: =IF($K16=0,100000,IF(Partecipanti!$B$9=$C16,100000,COUNTIF($S$6:$S15,Partecipanti!$B$9)*100+MOD(5-MATCH($C16,Partecipanti!$B$5:$B$9,0)-1,5))) | S16: =IF(OR($E16=0,$M16=1),"",IF(MIN($N16:$R16)>=100000,"DA ASSEGNARE",INDEX(Partecipanti!$B$5:$B$9,MATCH(MIN($N16:$R16),$N16:$R16,0)))) | T16: =IF(AND($F16=1,$S16<>"",$S16<>"DA ASSEGNARE"),$S16,"") | U16: =IF($M16=1,$L16,IF($E16=0,$C16,$S16)) | V16: =IF($M16=1,"Recupero",IF($E16=0,"Ordinario",IF($S16="DA ASSEGNARE","DA ASSEGNARE","Sostituzione (doppio turno)"))) | W16: =IF(OR($M16=1,$E16=1),$C16,"") | X16: =IF($M16=1,$L16&" recupera il turno saltato nella settimana "&($A16-1)&"; "&$C16&" a riposo compensativo",IF($E16=1,$C16&" assente ("&$D16&")"&IF($S16="DA ASSEGNARE","; nessun sostituto disponibile","; sostituisce "&$S16&" con doppio turno")&IF($F16=1,"; turno da recuperare nella settimana "&($A16+1),"; turno non da recuperare"),"")) | Y16: =IF($M16=1,"recupera il turno saltato nella settimana "&($A16-1)&", "&$C16&" a riposo",IF($E16=1,IF($S16="DA ASSEGNARE","turno da assegnare: "&$C16&" assente","in sostituzione di "&$C16&", doppio turno"),""))
A17: 3 | B17: 46308 | C17: =Partecipanti!$B$6 | D17: =IF(COUNTIFS(A_PERS,$C17,A_SETT,$A17,A_TIPO,"Licenza - settimana intera")>0,"Licenza - settimana intera",IF(COUNTIFS(A_PERS,$C17,A_SETT,$A17,A_TIPO,"Attività esterna - settimana intera")>0,"Attività esterna - settimana intera",IF(COUNTIFS(A_PERS,$C17,A_DATA,$B17)>0,INDEX(A_TIPO,MATCH(1,INDEX((A_PERS=$C17)*(A_DATA=$B17),0),0)),""))) | E17: =IF($D17="",0,1) | F17: =IF($E17=0,0,IF(OR($D17="Licenza - settimana intera",$D17="Attività esterna - settimana intera"),0,1)) | G17: =IF(COUNTIFS(A_PERS,Partecipanti!$B$5,A_DATA,$B17)+COUNTIFS(A_PERS,Partecipanti!$B$5,A_SETT,$A17,A_TIPO,"Licenza - settimana intera")+COUNTIFS(A_PERS,Partecipanti!$B$5,A_SETT,$A17,A_TIPO,"Attività esterna - settimana intera")>0,0,1) | H17: =IF(COUNTIFS(A_PERS,Partecipanti!$B$6,A_DATA,$B17)+COUNTIFS(A_PERS,Partecipanti!$B$6,A_SETT,$A17,A_TIPO,"Licenza - settimana intera")+COUNTIFS(A_PERS,Partecipanti!$B$6,A_SETT,$A17,A_TIPO,"Attività esterna - settimana intera")>0,0,1) | I17: =IF(COUNTIFS(A_PERS,Partecipanti!$B$7,A_DATA,$B17)+COUNTIFS(A_PERS,Partecipanti!$B$7,A_SETT,$A17,A_TIPO,"Licenza - settimana intera")+COUNTIFS(A_PERS,Partecipanti!$B$7,A_SETT,$A17,A_TIPO,"Attività esterna - settimana intera")>0,0,1) | J17: =IF(COUNTIFS(A_PERS,Partecipanti!$B$8,A_DATA,$B17)+COUNTIFS(A_PERS,Partecipanti!$B$8,A_SETT,$A17,A_TIPO,"Licenza - settimana intera")+COUNTIFS(A_PERS,Partecipanti!$B$8,A_SETT,$A17,A_TIPO,"Attività esterna - settimana intera")>0,0,1) | K17: =IF(COUNTIFS(A_PERS,Partecipanti!$B$9,A_DATA,$B17)+COUNTIFS(A_PERS,Partecipanti!$B$9,A_SETT,$A17,A_TIPO,"Licenza - settimana intera")+COUNTIFS(A_PERS,Partecipanti!$B$9,A_SETT,$A17,A_TIPO,"Attività esterna - settimana intera")>0,0,1) | L17: =IFERROR(INDEX($C11:$C15,MATCH(1,INDEX(($T11:$T15=$C17)*1,0),0)),"") | M17: =IF($L17="",0,IF(INDEX($G17:$K17,MATCH($L17,Partecipanti!$B$5:$B$9,0))=1,1,0)) | N17: =IF($G17=0,100000,IF(Partecipanti!$B$5=$C17,100000,COUNTIF($S$6:$S16,Partecipanti!$B$5)*100+MOD(1-MATCH($C17,Partecipanti!$B$5:$B$9,0)-1,5))) | O17: =IF($H17=0,100000,IF(Partecipanti!$B$6=$C17,100000,COUNTIF($S$6:$S16,Partecipanti!$B$6)*100+MOD(2-MATCH($C17,Partecipanti!$B$5:$B$9,0)-1,5))) | P17: =IF($I17=0,100000,IF(Partecipanti!$B$7=$C17,100000,COUNTIF($S$6:$S16,Partecipanti!$B$7)*100+MOD(3-MATCH($C17,Partecipanti!$B$5:$B$9,0)-1,5))) | Q17: =IF($J17=0,100000,IF(Partecipanti!$B$8=$C17,100000,COUNTIF($S$6:$S16,Partecipanti!$B$8)*100+MOD(4-MATCH($C17,Partecipanti!$B$5:$B$9,0)-1,5))) | R17: =IF($K17=0,100000,IF(Partecipanti!$B$9=$C17,100000,COUNTIF($S$6:$S16,Partecipanti!$B$9)*100+MOD(5-MATCH($C17,Partecipanti!$B$5:$B$9,0)-1,5))) | S17: =IF(OR($E17=0,$M17=1),"",IF(MIN($N17:$R17)>=100000,"DA ASSEGNARE",INDEX(Partecipanti!$B$5:$B$9,MATCH(MIN($N17:$R17),$N17:$R17,0)))) | T17: =IF(AND($F17=1,$S17<>"",$S17<>"DA ASSEGNARE"),$S17,"") | U17: =IF($M17=1,$L17,IF($E17=0,$C17,$S17)) | V17: =IF($M17=1,"Recupero",IF($E17=0,"Ordinario",IF($S17="DA ASSEGNARE","DA ASSEGNARE","Sostituzione (doppio turno)"))) | W17: =IF(OR($M17=1,$E17=1),$C17,"") | X17: =IF($M17=1,$L17&" recupera il turno saltato nella settimana "&($A17-1)&"; "&$C17&" a riposo compensativo",IF($E17=1,$C17&" assente ("&$D17&")"&IF($S17="DA ASSEGNARE","; nessun sostituto disponibile","; sostituisce "&$S17&" con doppio turno")&IF($F17=1,"; turno da recuperare nella settimana "&($A17+1),"; turno non da recuperare"),"")) | Y17: =IF($M17=1,"recupera il turno saltato nella settimana "&($A17-1)&", "&$C17&" a riposo",IF($E17=1,IF($S17="DA ASSEGNARE","turno da assegnare: "&$C17&" assente","in sostituzione di "&$C17&", doppio turno"),""))
